<?xml version="1.0"?>
<mujoco>
    <compiler angle="radian"/>
    <option collision="all" timestep="0.002"/>
    <size njmax="1000" nconmax="400"/>
    <default class="main">
        <default class="eye">
            <position ctrllimited="true" kp="5"/>
            <joint type="hinge" stiffness="0.0" damping="0.5" armature="0.0" limited="true"/>
        </default>
        <default class="grid">
            <geom type="box" size="0.0025 0.0001 0.0025" rgba="0.5 0.5 0.5 0"/>
        </default>
    </default>
    <asset>
        <texture type="skybox" builtin="gradient" rgb1="1 1 1" rgb2="0.6 0.8 1" width="256" height="256"/>
        <texture type="cube" name="blue-eye" file="assets/blue_eye_texture_circle.png" gridsize="3 4" gridlayout=".U..LFRB.D.."/>
        <material name="blue-eye" texture="blue-eye" texuniform="true"/>
        <mesh name="eye" file="assets/basic_eye_2.stl" scale="0.05 0.05 0.05"/>
    </asset>
    <worldbody>
        <light name="scene_directional_light" directional="true" castshadow="false" cutoff="4" exponent="20"
               diffuse="1 1 1" specular="0 0 0" pos=".9 .3 2.5"/>

        <camera name="env" pos="-0.1 -0.05 0.05" euler="1.0 -0.85 -0.37"/>

        <body name="eye" pos="0 0 0" quat="0.7071068 0.7071068 0 0">
            <geom name="eye" type="sphere" size="0.025" material="blue-eye" rgba="1 1 1 1" quat="0.6625191 0.0130711 0.7488417 0.0115643"/>
            <camera name="eye" fovy="90"/>
            <joint name="eye-joint-x" class="eye" axis="1 0 0" range="-0.5 0.5"/>
            <joint name="eye-joint-y" class="eye" axis="0 1 0" range="-0.5 0.5"/>
            <site name="rangefinder-site" quat="0 0 1 0"/>

            <geom name="fixate-point" pos="0 0 -0.04" type="sphere" size="0.001" rgba="0.8 0.8 0 0.5"/>
        </body>

        <body name="smart-glass-pane" pos="0 0.05 0">
            <geom name="grid-0" pos="-0.015 0 0.015" class="grid"/>
            <geom name="grid-1" pos="-0.005 0 0.015" class="grid"/>
            <geom name="grid-2" pos="0.005 0 0.015" class="grid"/>
            <geom name="grid-3" pos="0.015 0 0.015" class="grid"/>

            <geom name="grid-4" pos="-0.015 0 0.005" class="grid"/>
            <geom name="grid-5" pos="-0.005 0 0.005" class="grid"/>
            <geom name="grid-6" pos="0.005 0 0.005" class="grid"/>
            <geom name="grid-7" pos="0.015 0 0.005" class="grid"/>

            <geom name="grid-8" pos="-0.015 0 -0.005" class="grid"/>
            <geom name="grid-9" pos="-0.005 0 -0.005" class="grid"/>
            <geom name="grid-10" pos="0.005 0 -0.005" class="grid"/>
            <geom name="grid-11" pos="0.015 0 -0.005" class="grid"/>

            <geom name="grid-12" pos="-0.015 0 -0.015" class="grid"/>
            <geom name="grid-13" pos="-0.005 0 -0.015" class="grid"/>
            <geom name="grid-14" pos="0.005 0 -0.015" class="grid"/>
            <geom name="grid-15" pos="0.015 0 -0.015" class="grid"/>
        </body>

    </worldbody>
    <actuator>
        <position name="eye-x-motor" joint="eye-joint-x" class="eye" ctrlrange="-0.5 0.5"/>
        <position name="eye-y-motor" joint="eye-joint-y" class="eye" ctrlrange="-0.5 0.5"/>
    </actuator>
    <sensor>
        <rangefinder name="rangefinder" site="rangefinder-site"/>
    </sensor>
</mujoco>