<?xml version="1.0"?>
<mujoco>
    <compiler angle="radian"/>
    <option collision="predefined" timestep="0.002"/>
    <size njmax="1000" nconmax="400"/>
    <default class="main">
        <default class="eye">
            <position ctrllimited="true" kp="10"/>
            <joint type="hinge" stiffness="0.0" damping="0.05" armature="0.0" limited="true"/>
        </default>

        <default class="head-rotations">
            <position ctrllimited="true" kp="10"/>
            <joint type="hinge" stiffness="0.0" damping="0.25" armature="0.0" limited="true"/>
        </default>

        <default class="smart-glass-grid">
            <geom type="box" size="0.045 0.0000001 0.045" rgba="0 0 0 0"/>
        </default>

        <default class="agent-forward-locomotion">
            <position ctrllimited="true" kp="10"/>
            <joint type="slide" stiffness="0.0" damping="1.5" armature="0.0" limited="true"/>
        </default>

        <default class="agent-lane-change-locomotion">
            <position ctrllimited="true" kp="10"/>
            <joint type="slide" stiffness="0.0" damping="1.5" armature="0.0" limited="true"/>
        </default>
    </default>

    <asset>
        <texture type="skybox" builtin="gradient" rgb1="1 1 1" rgb2="0.6 0.8 1" width="256" height="256"/>
        <texture type="cube" name="blue-eye" file="assets/blue_eye_texture_circle.png" gridsize="3 4" gridlayout=".U..LFRB.D.."/>
        <material name="blue-eye" texture="blue-eye" texuniform="true"/>
        <mesh name="eye" file="assets/basic_eye_2.stl" scale="0.05 0.05 0.05"/>
        <mesh name="ribcage" file="assets/ribcage.stl" scale="0.25 0.25 0.25"/>
    </asset>

    <worldbody>
        <light name="scene_directional_light" directional="true" castshadow="false" cutoff="4" exponent="20"
               diffuse="1 1 1" specular="0 0 0" pos=".9 .3 2.5"/>

        <body name="straight-walk-path" pos="0 5 0">
            <geom name="straight-path" type="box" pos="0 0 0" size="0.5 5 0.0000001" rgba="0 0 0 1"/>
        </body>

        <body name="agent" pos="0 0 0.4">
            <geom name="ribcage" type="mesh" mesh="ribcage" pos="0 0 -0.15" euler="1.57 1.57 0" rgba="0.99 0.99 0.99 0.5"/>
            <camera name="env" pos="0 -1 0.15" euler="1.5 0 0"/>
            <joint name="agent-joint-y" class="agent-forward-locomotion" axis="0 1 0" range="0 200"/>
            <joint name="agent-joint-x" class="agent-lane-change-locomotion" axis="1 0 0" range="-1 1"/>

            <body name="eye" pos="0 0 0" quat="0.7071068 0.7071068 0 0">
                <geom name="eye" type="sphere" size="0.0125" material="blue-eye" rgba="1 1 1 1" quat="0.6625191 0.0130711 0.7488417 0.0115643"/>
                <camera name="eye" fovy="90"/>
                <joint name="eye-joint-x" class="eye" axis="1 0 0" range="-0.7854 0.7854"/>
                <joint name="eye-joint-y" class="eye" axis="0 1 0" range="-0.7854 0.7854"/>
                <site name="rangefinder-site" quat="0 0 1 0"/>
            </body>

            <body name="head" pos="0 0 0">
                <body name="smart-glass-pane-interline-spacing-100" pos="0 3 0">
    <!--                line gap = (3+1) * word height-->
                    <geom name="grid-1" pos="-0.225 0 0.36" class="smart-glass-grid"/>
                    <geom name="grid-2" pos="-0.075 0 0.36" class="smart-glass-grid"/>
                    <geom name="grid-3" pos="0.075 0 0.36" class="smart-glass-grid"/>
                    <geom name="grid-4" pos="0.225 0 0.36" class="smart-glass-grid"/>

                    <geom name="grid-5" pos="-0.225 0 0" class="smart-glass-grid"/>
                    <geom name="grid-6" pos="-0.075 0 0" class="smart-glass-grid"/>
                    <geom name="grid-7" pos="0.075 0 0" class="smart-glass-grid"/>
                    <geom name="grid-8" pos="0.225 0 0" class="smart-glass-grid"/>

                    <geom name="grid-9" pos="-0.225 0 -0.36" class="smart-glass-grid"/>
                    <geom name="grid-10" pos="-0.075 0 -0.36" class="smart-glass-grid"/>
                    <geom name="grid-11" pos="0.075 0 -0.36" class="smart-glass-grid"/>
                    <geom name="grid-12" pos="0.225 0 -0.36" class="smart-glass-grid"/>
                </body>

                <body name="smart-glass-pane-interline-spacing-50" pos="0 3 0">
    <!--                line gap = (1.5+1) * word height-->
                    <geom name="grid-13" pos="-0.225 0 0.225" class="smart-glass-grid"/>
                    <geom name="grid-14" pos="-0.075 0 0.225" class="smart-glass-grid"/>
                    <geom name="grid-15" pos="0.075 0 0.225" class="smart-glass-grid"/>
                    <geom name="grid-16" pos="0.225 0 0.225" class="smart-glass-grid"/>

                    <geom name="grid-17" pos="-0.225 0 0" class="smart-glass-grid"/>
                    <geom name="grid-18" pos="-0.075 0 0" class="smart-glass-grid"/>
                    <geom name="grid-19" pos="0.075 0 0" class="smart-glass-grid"/>
                    <geom name="grid-20" pos="0.225 0 0" class="smart-glass-grid"/>

                    <geom name="grid-21" pos="-0.225 0 -0.225" class="smart-glass-grid"/>
                    <geom name="grid-22" pos="-0.075 0 -0.225" class="smart-glass-grid"/>
                    <geom name="grid-23" pos="0.075 0 -0.225" class="smart-glass-grid"/>
                    <geom name="grid-24" pos="0.225 0 -0.225" class="smart-glass-grid"/>
                </body>

                <body name="smart-glass-pane-interline-spacing-0" pos="0 3 0">
    <!--                line gap = (0+1) * word height-->
                    <geom name="grid-25" pos="-0.225 0 0.10" class="smart-glass-grid"/>
                    <geom name="grid-26" pos="-0.075 0 0.10" class="smart-glass-grid"/>
                    <geom name="grid-27" pos="0.075 0 0.10" class="smart-glass-grid"/>
                    <geom name="grid-28" pos="0.225 0 0.10" class="smart-glass-grid"/>

                    <geom name="grid-29" pos="-0.225 0 0" class="smart-glass-grid"/>
                    <geom name="grid-30" pos="-0.075 0 0" class="smart-glass-grid"/>
                    <geom name="grid-31" pos="0.075 0 0" class="smart-glass-grid"/>
                    <geom name="grid-32" pos="0.225 0 0" class="smart-glass-grid"/>

                    <geom name="grid-33" pos="-0.225 0 -0.10" class="smart-glass-grid"/>
                    <geom name="grid-34" pos="-0.075 0 -0.10" class="smart-glass-grid"/>
                    <geom name="grid-35" pos="0.075 0 -0.10" class="smart-glass-grid"/>
                    <geom name="grid-36" pos="0.225 0 -0.10" class="smart-glass-grid"/>
                </body>
                <joint name="head-joint-x" class="head-rotations" axis="1 0 0" range="-1 1"/>
                <joint name="head-joint-z" class="head-rotations" axis="0 0 1" range="-1 1"/>
            </body>
        </body>
    </worldbody>

    <actuator>
        <position name="eye-x-motor" joint="eye-joint-x" class="eye" ctrlrange="-0.7854 0.7854"/>
        <position name="eye-y-motor" joint="eye-joint-y" class="eye" ctrlrange="-0.7854 0.7854"/>
        <position name="head-x-motor" joint="head-joint-x" class="head-rotations" ctrlrange="-0.07 0.07"/>
        <position name="head-z-motor" joint="head-joint-z" class="head-rotations" ctrlrange="-0.15 0.15"/>
        <position name="agent-y-motor" joint="agent-joint-y" class="agent-forward-locomotion" ctrlrange="0 200"/>
        <position name="agent-x-motor" joint="agent-joint-x" class="agent-lane-change-locomotion" ctrlrange="-1 1"/>
    </actuator>

    <sensor>
        <rangefinder name="rangefinder" site="rangefinder-site"/>
    </sensor>
</mujoco>
