<?xml version="1.0"?>
<mujoco>
    <compiler angle="radian"/>
    <option collision="predefined" timestep="0.002"/>
    <size njmax="1000" nconmax="400"/>
    <default class="main">
        <default class="eye">
            <position ctrllimited="true" kp="10"/>
            <joint type="hinge" stiffness="0.0" damping="0.05" armature="0.0" limited="true"/>
        </default>

        <default class="head-rotations">
            <position ctrllimited="true" kp="10"/>
            <joint type="hinge" stiffness="0.0" damping="0.25" armature="0.0" limited="true"/>
        </default>

        <default class="smart-glass-grid">
            <geom type="box" size="0.045 0.0000001 0.045" rgba="0 0 0 0"/>
        </default>

    </default>
    <asset>
        <texture type="skybox" builtin="gradient" rgb1="1 1 1" rgb2="0.6 0.8 1" width="256" height="256"/>
        <texture type="cube" name="blue-eye" file="assets/blue_eye_texture_circle.png" gridsize="3 4" gridlayout=".U..LFRB.D.."/>
        <material name="blue-eye" texture="blue-eye" texuniform="true"/>
        <mesh name="eye" file="assets/basic_eye_2.stl" scale="0.05 0.05 0.05"/>
    </asset>
    <worldbody>
        <light name="scene_directional_light" directional="true" castshadow="false" cutoff="4" exponent="20"
               diffuse="1 1 1" specular="0 0 0" pos=".9 .3 2.5"/>

        <camera name="env" pos="0.35 -0.35 0.15" euler="1.4 0.5 0.12"/>

        <body name="eye" pos="0 0 0" quat="0.7071068 0.7071068 0 0">
                <geom name="eye" type="sphere" size="0.0125" material="blue-eye" rgba="1 1 1 1" quat="0.6625191 0.0130711 0.7488417 0.0115643"/>
                <camera name="eye" fovy="90"/>
                <joint name="eye-joint-x" class="eye" axis="1 0 0" range="-0.7854 0.7854"/>
                <joint name="eye-joint-y" class="eye" axis="0 1 0" range="-0.7854 0.7854"/>
                <site name="rangefinder-site" quat="0 0 1 0"/>
        </body>

        <body name="head" pos="0 0 0">
            <body name="smart-glass-pane-interline-spacing-100" pos="0 3 0">
<!--                line gap = (3+1) * word height-->
                <geom name="grid-1" pos="-0.525 0 0.54" class="smart-glass-grid"/>
                <geom name="grid-2" pos="-0.375 0 0.54" class="smart-glass-grid"/>
                <geom name="grid-3" pos="-0.225 0 0.54" class="smart-glass-grid"/>
                <geom name="grid-4" pos="-0.075 0 0.54" class="smart-glass-grid"/>
                <geom name="grid-5" pos="0.075 0 0.54" class="smart-glass-grid"/>
                <geom name="grid-6" pos="0.225 0 0.54" class="smart-glass-grid"/>
                <geom name="grid-7" pos="0.375 0 0.54" class="smart-glass-grid"/>
                <geom name="grid-8" pos="0.525 0 0.54" class="smart-glass-grid"/>

                <geom name="grid-9" pos="-0.525 0 0.18" class="smart-glass-grid"/>
                <geom name="grid-10" pos="-0.375 0 0.18" class="smart-glass-grid"/>
                <geom name="grid-11" pos="-0.225 0 0.18" class="smart-glass-grid"/>
                <geom name="grid-12" pos="-0.075 0 0.18" class="smart-glass-grid"/>
                <geom name="grid-13" pos="0.075 0 0.18" class="smart-glass-grid"/>
                <geom name="grid-14" pos="0.225 0 0.18" class="smart-glass-grid"/>
                <geom name="grid-15" pos="0.375 0 0.18" class="smart-glass-grid"/>
                <geom name="grid-16" pos="0.525 0 0.18" class="smart-glass-grid"/>

                <geom name="grid-17" pos="-0.525 0 -0.18" class="smart-glass-grid"/>
                <geom name="grid-18" pos="-0.375 0 -0.18" class="smart-glass-grid"/>
                <geom name="grid-19" pos="-0.225 0 -0.18" class="smart-glass-grid"/>
                <geom name="grid-20" pos="-0.075 0 -0.18" class="smart-glass-grid"/>
                <geom name="grid-21" pos="0.075 0 -0.18" class="smart-glass-grid"/>
                <geom name="grid-22" pos="0.225 0 -0.18" class="smart-glass-grid"/>
                <geom name="grid-23" pos="0.375 0 -0.18" class="smart-glass-grid"/>
                <geom name="grid-24" pos="0.525 0 -0.18" class="smart-glass-grid"/>

                <geom name="grid-25" pos="-0.525 0 -0.54" class="smart-glass-grid"/>
                <geom name="grid-26" pos="-0.375 0 -0.54" class="smart-glass-grid"/>
                <geom name="grid-27" pos="-0.225 0 -0.54" class="smart-glass-grid"/>
                <geom name="grid-28" pos="-0.075 0 -0.54" class="smart-glass-grid"/>
                <geom name="grid-29" pos="0.075 0 -0.54" class="smart-glass-grid"/>
                <geom name="grid-30" pos="0.225 0 -0.54" class="smart-glass-grid"/>
                <geom name="grid-31" pos="0.375 0 -0.54" class="smart-glass-grid"/>
                <geom name="grid-32" pos="0.525 0 -0.54" class="smart-glass-grid"/>
            </body>

            <body name="smart-glass-pane-interline-spacing-50" pos="0 3 0">
<!--                line gap = (1.5+1) * word height-->
                <geom name="grid-33" pos="-0.525 0 0.3375" class="smart-glass-grid"/>
                <geom name="grid-34" pos="-0.375 0 0.3375" class="smart-glass-grid"/>
                <geom name="grid-35" pos="-0.225 0 0.3375" class="smart-glass-grid"/>
                <geom name="grid-36" pos="-0.075 0 0.3375" class="smart-glass-grid"/>
                <geom name="grid-37" pos="0.075 0 0.3375" class="smart-glass-grid"/>
                <geom name="grid-38" pos="0.225 0 0.3375" class="smart-glass-grid"/>
                <geom name="grid-39" pos="0.375 0 0.3375" class="smart-glass-grid"/>
                <geom name="grid-40" pos="0.525 0 0.3375" class="smart-glass-grid"/>

                <geom name="grid-41" pos="-0.525 0 0.1125" class="smart-glass-grid"/>
                <geom name="grid-42" pos="-0.375 0 0.1125" class="smart-glass-grid"/>
                <geom name="grid-43" pos="-0.225 0 0.1125" class="smart-glass-grid"/>
                <geom name="grid-44" pos="-0.075 0 0.1125" class="smart-glass-grid"/>
                <geom name="grid-45" pos="0.075 0 0.1125" class="smart-glass-grid"/>
                <geom name="grid-46" pos="0.225 0 0.1125" class="smart-glass-grid"/>
                <geom name="grid-47" pos="0.375 0 0.1125" class="smart-glass-grid"/>
                <geom name="grid-48" pos="0.525 0 0.1125" class="smart-glass-grid"/>

                <geom name="grid-49" pos="-0.525 0 -0.1125" class="smart-glass-grid"/>
                <geom name="grid-50" pos="-0.375 0 -0.1125" class="smart-glass-grid"/>
                <geom name="grid-51" pos="-0.225 0 -0.1125" class="smart-glass-grid"/>
                <geom name="grid-52" pos="-0.075 0 -0.1125" class="smart-glass-grid"/>
                <geom name="grid-53" pos="0.075 0 -0.1125" class="smart-glass-grid"/>
                <geom name="grid-54" pos="0.225 0 -0.1125" class="smart-glass-grid"/>
                <geom name="grid-55" pos="0.375 0 -0.1125" class="smart-glass-grid"/>
                <geom name="grid-56" pos="0.525 0 -0.1125" class="smart-glass-grid"/>

                <geom name="grid-57" pos="-0.525 0 -0.3375" class="smart-glass-grid"/>
                <geom name="grid-58" pos="-0.375 0 -0.3375" class="smart-glass-grid"/>
                <geom name="grid-59" pos="-0.225 0 -0.3375" class="smart-glass-grid"/>
                <geom name="grid-60" pos="-0.075 0 -0.3375" class="smart-glass-grid"/>
                <geom name="grid-61" pos="0.075 0 -0.3375" class="smart-glass-grid"/>
                <geom name="grid-62" pos="0.225 0 -0.3375" class="smart-glass-grid"/>
                <geom name="grid-63" pos="0.375 0 -0.3375" class="smart-glass-grid"/>
                <geom name="grid-64" pos="0.525 0 -0.3375" class="smart-glass-grid"/>
            </body>

            <body name="smart-glass-pane-interline-spacing-0" pos="0 3 0">
<!--                line gap = (0+1) * word height-->
                <geom name="grid-65" pos="-0.525 0 0.15" class="smart-glass-grid"/>
                <geom name="grid-66" pos="-0.375 0 0.15" class="smart-glass-grid"/>
                <geom name="grid-67" pos="-0.225 0 0.15" class="smart-glass-grid"/>
                <geom name="grid-68" pos="-0.075 0 0.15" class="smart-glass-grid"/>
                <geom name="grid-69" pos="0.075 0 0.15" class="smart-glass-grid"/>
                <geom name="grid-70" pos="0.225 0 0.15" class="smart-glass-grid"/>
                <geom name="grid-71" pos="0.375 0 0.15" class="smart-glass-grid"/>
                <geom name="grid-72" pos="0.525 0 0.15" class="smart-glass-grid"/>

                <geom name="grid-73" pos="-0.525 0 0.05" class="smart-glass-grid"/>
                <geom name="grid-74" pos="-0.375 0 0.05" class="smart-glass-grid"/>
                <geom name="grid-75" pos="-0.225 0 0.05" class="smart-glass-grid"/>
                <geom name="grid-76" pos="-0.075 0 0.05" class="smart-glass-grid"/>
                <geom name="grid-77" pos="0.075 0 0.05" class="smart-glass-grid"/>
                <geom name="grid-78" pos="0.225 0 0.05" class="smart-glass-grid"/>
                <geom name="grid-79" pos="0.375 0 0.05" class="smart-glass-grid"/>
                <geom name="grid-80" pos="0.525 0 0.05" class="smart-glass-grid"/>

                <geom name="grid-81" pos="-0.525 0 -0.05" class="smart-glass-grid"/>
                <geom name="grid-82" pos="-0.375 0 -0.05" class="smart-glass-grid"/>
                <geom name="grid-83" pos="-0.225 0 -0.05" class="smart-glass-grid"/>
                <geom name="grid-84" pos="-0.075 0 -0.05" class="smart-glass-grid"/>
                <geom name="grid-85" pos="0.075 0 -0.05" class="smart-glass-grid"/>
                <geom name="grid-86" pos="0.225 0 -0.05" class="smart-glass-grid"/>
                <geom name="grid-87" pos="0.375 0 -0.05" class="smart-glass-grid"/>
                <geom name="grid-88" pos="0.525 0 -0.05" class="smart-glass-grid"/>

                <geom name="grid-89" pos="-0.525 0 -0.15" class="smart-glass-grid"/>
                <geom name="grid-90" pos="-0.375 0 -0.15" class="smart-glass-grid"/>
                <geom name="grid-91" pos="-0.225 0 -0.15" class="smart-glass-grid"/>
                <geom name="grid-92" pos="-0.075 0 -0.15" class="smart-glass-grid"/>
                <geom name="grid-93" pos="0.075 0 -0.15" class="smart-glass-grid"/>
                <geom name="grid-94" pos="0.225 0 -0.15" class="smart-glass-grid"/>
                <geom name="grid-95" pos="0.375 0 -0.15" class="smart-glass-grid"/>
                <geom name="grid-96" pos="0.525 0 -0.15" class="smart-glass-grid"/>
            </body>

            <joint name="head-joint-x" class="head-rotations" axis="1 0 0" range="-1 1"/>
            <joint name="head-joint-z" class="head-rotations" axis="0 0 1" range="-1 1"/>
        </body>

    </worldbody>
    <actuator>
        <position name="eye-x-motor" joint="eye-joint-x" class="eye" ctrlrange="-0.7854 0.7854"/>
        <position name="eye-y-motor" joint="eye-joint-y" class="eye" ctrlrange="-0.7854 0.7854"/>
        <position name="head-x-motor" joint="head-joint-x" class="head-rotations" ctrlrange="-0.07 0.07"/>
        <position name="head-z-motor" joint="head-joint-z" class="head-rotations" ctrlrange="-0.15 0.15"/>
    </actuator>
    <sensor>
        <rangefinder name="rangefinder" site="rangefinder-site"/>
    </sensor>
</mujoco>
